Workbook

Sheet Model
A1: CELSIUS FOOD COST MODEL - APR-JUL 2026 (all live formulas)
A2: Yellow cells are editable. Edit a dose or true cost, or correct a PO Ledger line - every number here recalculates.
A3: Tabs: Model (assumptions + results) | Sales Ledger (every menu x month x dose = expected usage) | PO Ledger (every purchase line = actual)
A5: 1. ASSUMPTIONS
A6: Ingredient | B6: UOM | C6: True cost RM/base unit (EDIT) | D6: Note
A7: Home Blend (Collective) | B7: g | C7: 0.093 | D7: RM93/kg beans
A8: Fresh Milk | B8: ml | C8: 0.007 | D8: RM7/L TRUE price (not package-bug price)
A9: Brioche Sandwich | B9: pcs | C9: 1.55 | D9: RM15.50 per 10-pc loaf
A10: Telur Omega | B10: pcs | C10: 0.76 | D10: per egg
A11: Burnt Cheesecake | B11: pcs | C11: 8.33 | D11: per slice
A12: Salted Croissant | B12: pcs | C12: 6.09 | D12: per pc
A13: Udang | B13: g | C13: 0.016 | D13: RM16/kg
A14: Pull Lamb | B14: g | C14: 0.129 | D14: per g
A16: Plan COGS % | B16: 0.38
A18: 2. MONTHLY TOP-DOWN (bank cash lens)
A19: Month | B19: Revenue RM | C19: Cash raw materials RM | D19: Cash % | E19: Gap vs plan RM
A20: 2026-04 | B20: 335719 | C20: 152525 | D20: =C20/B20 | E20: =C20-B20*$B$16
A21: 2026-05 | B21: 349775 | C21: 148791 | D21: =C21/B21 | E21: =C21-B21*$B$16
A22: 2026-06 | B22: 324584 | C22: 148522 | D22: =C22/B22 | E22: =C22-B22*$B$16
A23: 2026-07 | B23: 290251 | C23: 114754 | D23: =C23/B23 | E23: =C23-B23*$B$16
A24: TOTAL | B24: =SUM(B20:B23) | C24: =SUM(C20:C23) | D24: =C24/B24 | E24: =SUM(E20:E23)
A26: 3. ANALYSIS - ingredient x month (formulas over the two ledger tabs)
A27: Ingredient | B27: Month | C27: Items sold | D27: Expected usage | E27: Purchased (recorded) | F27: Spend RM | G27: True cost/unit | H27: Purchased @true cost | I27: Ratio true/expected | J27: Excess RM
A28: Home Blend (Collective) | B28: 2026-04 | C28: =SUMIFS('Sales Ledger'!$D$2:$D$294,'Sales Ledger'!$A$2:$A$294,$A28,'Sales Ledger'!$C$2:$C$294,$B28) | D28: =SUMIFS('Sales Ledger'!$F$2:$F$294,'Sales Ledger'!$A$2:$A$294,$A28,'Sales Ledger'!$C$2:$C$294,$B28) | E28: =SUMIFS('PO Ledger'!$J$2:$J$384,'PO Ledger'!$F$2:$F$384,$A28,'PO Ledger'!$A$2:$A$384,$B28) | F28: =SUMIFS('PO Ledger'!$L$2:$L$384,'PO Ledger'!$F$2:$F$384,$A28,'PO Ledger'!$A$2:$A$384,$B28) | G28: =VLOOKUP($A28,$A$7:$D$14,3,0) | H28: =IF(G28>0,F28/G28,E28) | I28: =IF(D28>0,H28/D28,"") | J28: =MAX(0,F28-D28*G28)
A29: Home Blend (Collective) | B29: 2026-05 | C29: =SUMIFS('Sales Ledger'!$D$2:$D$294,'Sales Ledger'!$A$2:$A$294,$A29,'Sales Ledger'!$C$2:$C$294,$B29) | D29: =SUMIFS('Sales Ledger'!$F$2:$F$294,'Sales Ledger'!$A$2:$A$294,$A29,'Sales Ledger'!$C$2:$C$294,$B29) | E29: =SUMIFS('PO Ledger'!$J$2:$J$384,'PO Ledger'!$F$2:$F$384,$A29,'PO Ledger'!$A$2:$A$384,$B29) | F29: =SUMIFS('PO Ledger'!$L$2:$L$384,'PO Ledger'!$F$2:$F$384,$A29,'PO Ledger'!$A$2:$A$384,$B29) | G29: =VLOOKUP($A29,$A$7:$D$14,3,0) | H29: =IF(G29>0,F29/G29,E29) | I29: =IF(D29>0,H29/D29,"") | J29: =MAX(0,F29-D29*G29)
A30: Home Blend (Collective) | B30: 2026-06 | C30: =SUMIFS('Sales Ledger'!$D$2:$D$294,'Sales Ledger'!$A$2:$A$294,$A30,'Sales Ledger'!$C$2:$C$294,$B30) | D30: =SUMIFS('Sales Ledger'!$F$2:$F$294,'Sales Ledger'!$A$2:$A$294,$A30,'Sales Ledger'!$C$2:$C$294,$B30) | E30: =SUMIFS('PO Ledger'!$J$2:$J$384,'PO Ledger'!$F$2:$F$384,$A30,'PO Ledger'!$A$2:$A$384,$B30) | F30: =SUMIFS('PO Ledger'!$L$2:$L$384,'PO Ledger'!$F$2:$F$384,$A30,'PO Ledger'!$A$2:$A$384,$B30) | G30: =VLOOKUP($A30,$A$7:$D$14,3,0) | H30: =IF(G30>0,F30/G30,E30) | I30: =IF(D30>0,H30/D30,"") | J30: =MAX(0,F30-D30*G30)
A31: Home Blend (Collective) | B31: 2026-07 | C31: =SUMIFS('Sales Ledger'!$D$2:$D$294,'Sales Ledger'!$A$2:$A$294,$A31,'Sales Ledger'!$C$2:$C$294,$B31) | D31: =SUMIFS('Sales Ledger'!$F$2:$F$294,'Sales Ledger'!$A$2:$A$294,$A31,'Sales Ledger'!$C$2:$C$294,$B31) | E31: =SUMIFS('PO Ledger'!$J$2:$J$384,'PO Ledger'!$F$2:$F$384,$A31,'PO Ledger'!$A$2:$A$384,$B31) | F31: =SUMIFS('PO Ledger'!$L$2:$L$384,'PO Ledger'!$F$2:$F$384,$A31,'PO Ledger'!$A$2:$A$384,$B31) | G31: =VLOOKUP($A31,$A$7:$D$14,3,0) | H31: =IF(G31>0,F31/G31,E31) | I31: =IF(D31>0,H31/D31,"") | J31: =MAX(0,F31-D31*G31)
A32: Fresh Milk | B32: 2026-04 | C32: =SUMIFS('Sales Ledger'!$D$2:$D$294,'Sales Ledger'!$A$2:$A$294,$A32,'Sales Ledger'!$C$2:$C$294,$B32) | D32: =SUMIFS('Sales Ledger'!$F$2:$F$294,'Sales Ledger'!$A$2:$A$294,$A32,'Sales Ledger'!$C$2:$C$294,$B32) | E32: =SUMIFS('PO Ledger'!$J$2:$J$384,'PO Ledger'!$F$2:$F$384,$A32,'PO Ledger'!$A$2:$A$384,$B32) | F32: =SUMIFS('PO Ledger'!$L$2:$L$384,'PO Ledger'!$F$2:$F$384,$A32,'PO Ledger'!$A$2:$A$384,$B32) | G32: =VLOOKUP($A32,$A$7:$D$14,3,0) | H32: =IF(G32>0,F32/G32,E32) | I32: =IF(D32>0,H32/D32,"") | J32: =MAX(0,F32-D32*G32)
A33: Fresh Milk | B33: 2026-05 | C33: =SUMIFS('Sales Ledger'!$D$2:$D$294,'Sales Ledger'!$A$2:$A$294,$A33,'Sales Ledger'!$C$2:$C$294,$B33) | D33: =SUMIFS('Sales Ledger'!$F$2:$F$294,'Sales Ledger'!$A$2:$A$294,$A33,'Sales Ledger'!$C$2:$C$294,$B33) | E33: =SUMIFS('PO Ledger'!$J$2:$J$384,'PO Ledger'!$F$2:$F$384,$A33,'PO Ledger'!$A$2:$A$384,$B33) | F33: =SUMIFS('PO Ledger'!$L$2:$L$384,'PO Ledger'!$F$2:$F$384,$A33,'PO Ledger'!$A$2:$A$384,$B33) | G33: =VLOOKUP($A33,$A$7:$D$14,3,0) | H33: =IF(G33>0,F33/G33,E33) | I33: =IF(D33>0,H33/D33,"") | J33: =MAX(0,F33-D33*G33)
A34: Fresh Milk | B34: 2026-06 | C34: =SUMIFS('Sales Ledger'!$D$2:$D$294,'Sales Ledger'!$A$2:$A$294,$A34,'Sales Ledger'!$C$2:$C$294,$B34) | D34: =SUMIFS('Sales Ledger'!$F$2:$F$294,'Sales Ledger'!$A$2:$A$294,$A34,'Sales Ledger'!$C$2:$C$294,$B34) | E34: =SUMIFS('PO Ledger'!$J$2:$J$384,'PO Ledger'!$F$2:$F$384,$A34,'PO Ledger'!$A$2:$A$384,$B34) | F34: =SUMIFS('PO Ledger'!$L$2:$L$384,'PO Ledger'!$F$2:$F$384,$A34,'PO Ledger'!$A$2:$A$384,$B34) | G34: =VLOOKUP($A34,$A$7:$D$14,3,0) | H34: =IF(G34>0,F34/G34,E34) | I34: =IF(D34>0,H34/D34,"") | J34: =MAX(0,F34-D34*G34)
A35: Fresh Milk | B35: 2026-07 | C35: =SUMIFS('Sales Ledger'!$D$2:$D$294,'Sales Ledger'!$A$2:$A$294,$A35,'Sales Ledger'!$C$2:$C$294,$B35) | D35: =SUMIFS('Sales Ledger'!$F$2:$F$294,'Sales Ledger'!$A$2:$A$294,$A35,'Sales Ledger'!$C$2:$C$294,$B35) | E35: =SUMIFS('PO Ledger'!$J$2:$J$384,'PO Ledger'!$F$2:$F$384,$A35,'PO Ledger'!$A$2:$A$384,$B35) | F35: =SUMIFS('PO Ledger'!$L$2:$L$384,'PO Ledger'!$F$2:$F$384,$A35,'PO Ledger'!$A$2:$A$384,$B35) | G35: =VLOOKUP($A35,$A$7:$D$14,3,0) | H35: =IF(G35>0,F35/G35,E35) | I35: =IF(D35>0,H35/D35,"") | J35: =MAX(0,F35-D35*G35)
A36: Brioche Sandwich | B36: 2026-04 | C36: =SUMIFS('Sales Ledger'!$D$2:$D$294,'Sales Ledger'!$A$2:$A$294,$A36,'Sales Ledger'!$C$2:$C$294,$B36) | D36: =SUMIFS('Sales Ledger'!$F$2:$F$294,'Sales Ledger'!$A$2:$A$294,$A36,'Sales Ledger'!$C$2:$C$294,$B36) | E36: =SUMIFS('PO Ledger'!$J$2:$J$384,'PO Ledger'!$F$2:$F$384,$A36,'PO Ledger'!$A$2:$A$384,$B36) | F36: =SUMIFS('PO Ledger'!$L$2:$L$384,'PO Ledger'!$F$2:$F$384,$A36,'PO Ledger'!$A$2:$A$384,$B36) | G36: =VLOOKUP($A36,$A$7:$D$14,3,0) | H36: =IF(G36>0,F36/G36,E36) | I36: =IF(D36>0,H36/D36,"") | J36: =MAX(0,F36-D36*G36)
A37: Brioche Sandwich | B37: 2026-05 | C37: =SUMIFS('Sales Ledger'!$D$2:$D$294,'Sales Ledger'!$A$2:$A$294,$A37,'Sales Ledger'!$C$2:$C$294,$B37) | D37: =SUMIFS('Sales Ledger'!$F$2:$F$294,'Sales Ledger'!$A$2:$A$294,$A37,'Sales Ledger'!$C$2:$C$294,$B37) | E37: =SUMIFS('PO Ledger'!$J$2:$J$384,'PO Ledger'!$F$2:$F$384,$A37,'PO Ledger'!$A$2:$A$384,$B37) | F37: =SUMIFS('PO Ledger'!$L$2:$L$384,'PO Ledger'!$F$2:$F$384,$A37,'PO Ledger'!$A$2:$A$384,$B37) | G37: =VLOOKUP($A37,$A$7:$D$14,3,0) | H37: =IF(G37>0,F37/G37,E37) | I37: =IF(D37>0,H37/D37,"") | J37: =MAX(0,F37-D37*G37)
A38: Brioche Sandwich | B38: 2026-06 | C38: =SUMIFS('Sales Ledger'!$D$2:$D$294,'Sales Ledger'!$A$2:$A$294,$A38,'Sales Ledger'!$C$2:$C$294,$B38) | D38: =SUMIFS('Sales Ledger'!$F$2:$F$294,'Sales Ledger'!$A$2:$A$294,$A38,'Sales Ledger'!$C$2:$C$294,$B38) | E38: =SUMIFS('PO Ledger'!$J$2:$J$384,'PO Ledger'!$F$2:$F$384,$A38,'PO Ledger'!$A$2:$A$384,$B38) | F38: =SUMIFS('PO Ledger'!$L$2:$L$384,'PO Ledger'!$F$2:$F$384,$A38,'PO Ledger'!$A$2:$A$384,$B38) | G38: =VLOOKUP($A38,$A$7:$D$14,3,0) | H38: =IF(G38>0,F38/G38,E38) | I38: =IF(D38>0,H38/D38,"") | J38: =MAX(0,F38-D38*G38)
A39: Brioche Sandwich | B39: 2026-07 | C39: =SUMIFS('Sales Ledger'!$D$2:$D$294,'Sales Ledger'!$A$2:$A$294,$A39,'Sales Ledger'!$C$2:$C$294,$B39) | D39: =SUMIFS('Sales Ledger'!$F$2:$F$294,'Sales Ledger'!$A$2:$A$294,$A39,'Sales Ledger'!$C$2:$C$294,$B39) | E39: =SUMIFS('PO Ledger'!$J$2:$J$384,'PO Ledger'!$F$2:$F$384,$A39,'PO Ledger'!$A$2:$A$384,$B39) | F39: =SUMIFS('PO Ledger'!$L$2:$L$384,'PO Ledger'!$F$2:$F$384,$A39,'PO Ledger'!$A$2:$A$384,$B39) | G39: =VLOOKUP($A39,$A$7:$D$14,3,0) | H39: =IF(G39>0,F39/G39,E39) | I39: =IF(D39>0,H39/D39,"") | J39: =MAX(0,F39-D39*G39)
... A59: Pull Lamb | B59: 2026-07 | C59: =SUMIFS('Sales Ledger'!$D$2:$D$294,'Sales Ledger'!$A$2:$A$294,$A59,'Sales Ledger'!$C$2:$C$294,$B59) | D59: =SUMIFS('Sales Ledger'!$F$2:$F$294,'Sales Ledger'!$A$2:$A$294,$A59,'Sales Ledger'!$C$2:$C$294,$B59) | E59: =SUMIFS('PO Ledger'!$J$2:$J$384,'PO Ledger'!$F$2:$F$384,$A59,'PO Ledger'!$A$2:$A$384,$B59) | F59: =SUMIFS('PO Ledger'!$L$2:$L$384,'PO Ledger'!$F$2:$F$384,$A59,'PO Ledger'!$A$2:$A$384,$B59) | G59: =VLOOKUP($A59,$A$7:$D$14,3,0) | H59: =IF(G59>0,F59/G59,E59) | I59: =IF(D59>0,H59/D59,"") | J59: =MAX(0,F59-D59*G59)
A61: 4. CUMULATIVE APR-JUL (auto; April POs undercount - system adoption)
A62: Ingredient | B62: Expected | C62: Purchased @true | D62: Spend RM | E62: Ratio | F62: Excess RM | G62: Excess/month
A63: Home Blend (Collective) | B63: =SUMIFS($D$28:$D$59,$A$28:$A$59,$A63) | C63: =SUMIFS($H$28:$H$59,$A$28:$A$59,$A63) | D63: =SUMIFS($F$28:$F$59,$A$28:$A$59,$A63) | E63: =IF(B63>0,C63/B63,"") | F63: =SUMIFS($J$28:$J$59,$A$28:$A$59,$A63) | G63: =F63/4
A64: Fresh Milk | B64: =SUMIFS($D$28:$D$59,$A$28:$A$59,$A64) | C64: =SUMIFS($H$28:$H$59,$A$28:$A$59,$A64) | D64: =SUMIFS($F$28:$F$59,$A$28:$A$59,$A64) | E64: =IF(B64>0,C64/B64,"") | F64: =SUMIFS($J$28:$J$59,$A$28:$A$59,$A64) | G64: =F64/4
...

Sheet Sales Ledger
A1: Ingredient | B1: Menu item | C1: Month | D1: Qty sold | E1: Dose per item (EDIT) | F1: Usage = qty x dose
A2: Home Blend (Collective) | B2: Latte | C2: 2026-04 | D2: 2834 | E2: 18 | F2: =D2*E2
A3: Home Blend (Collective) | B3: Latte | C3: 2026-05 | D3: 2797 | E3: 18 | F3: =D3*E3
A4: Home Blend (Collective) | B4: Latte | C4: 2026-06 | D4: 2730 | E4: 18 | F4: =D4*E4
A5: Home Blend (Collective) | B5: Latte | C5: 2026-07 | D5: 2548 | E5: 18 | F5: =D5*E5
A6: Home Blend (Collective) | B6: Buttercream Latte | C6: 2026-04 | D6: 1604 | E6: 18 | F6: =D6*E6
A7: Home Blend (Collective) | B7: Buttercream Latte | C7: 2026-05 | D7: 1542 | E7: 18 | F7: =D7*E7
A8: Home Blend (Collective) | B8: Buttercream Latte | C8: 2026-06 | D8: 1384 | E8: 18 | F8: =D8*E8
A9: Home Blend (Collective) | B9: Buttercream Latte | C9: 2026-07 | D9: 1267 | E9: 18 | F9: =D9*E9
A10: Home Blend (Collective) | B10: Black | C10: 2026-04 | D10: 1417 | E10: 18 | F10: =D10*E10
A11: Home Blend (Collective) | B11: Black | C11: 2026-05 | D11: 1366 | E11: 18 | F11: =D11*E11
A12: Home Blend (Collective) | B12: Black | C12: 2026-06 | D12: 1228 | E12: 18 | F12: =D12*E12
A13: Home Blend (Collective) | B13: Black | C13: 2026-07 | D13: 1055 | E13: 18 | F13: =D13*E13
... A294: Pull Lamb | B294: Smoked Pulled Lamb | C294: 2026-07 | D294: 92 | E294: 50 | F294: =D294*E294

Sheet PO Ledger
A1: Month | B1: Date | C1: PO number | D1: Outlet | E1: Supplier | F1: Product | G1: Package | H1: Qty (EDIT) | I1: Conversion (EDIT) | J1: Base units = qty x conv | K1: Unit RM | L1: Line total RM
A2: 2026-05 | B2: 2026-05-11 | C2: CC-CC001-0108 | D2: PJ | E2: Country Bread | F2: Brioche Sandwich | G2: 10pcs Loaf | H2: 28 | I2: 10 | J2: =H2*I2 | K2: 15.5 | L2: 434
A3: 2026-05 | B3: 2026-05-11 | C3: CC-CC001-0109 | D3: PJ | E3: Country Bread | F3: Brioche Sandwich | G3: 10pcs Loaf | H3: 24 | I3: 10 | J3: =H3*I3 | K3: 15.5 | L3: 372
A4: 2026-05 | B4: 2026-05-11 | C4: CC-CC003-0059 | D4: TAM | E4: Country Bread | F4: Brioche Sandwich | G4: 10pcs Loaf | H4: 12 | I4: 10 | J4: =H4*I4 | K4: 15.5 | L4: 186
A5: 2026-05 | B5: 2026-05-11 | C5: CC-CC002-0089 | D5: SA | E5: Country Bread | F5: Brioche Sandwich | G5: 10pcs Loaf | H5: 12 | I5: 10 | J5: =H5*I5 | K5: 15.5 | L5: 186
A6: 2026-05 | B6: 2026-05-11 | C6: CC-CC003-0060 | D6: TAM | E6: Country Bread | F6: Brioche Sandwich | G6: 10pcs Loaf | H6: 24 | I6: 10 | J6: =H6*I6 | K6: 15.5 | L6: 372
A7: 2026-05 | B7: 2026-05-11 | C7: CC-CC003-0061 | D7: TAM | E7: Country Bread | F7: Brioche Sandwich | G7: 10pcs Loaf | H7: 15 | I7: 10 | J7: =H7*I7 | K7: 15.5 | L7: 232.5
A8: 2026-05 | B8: 2026-05-11 | C8: CC-CC002-0090 | D8: SA | E8: Country Bread | F8: Brioche Sandwich | G8: 10pcs Loaf | H8: 12 | I8: 10 | J8: =H8*I8 | K8: 15.5 | L8: 186
A9: 2026-05 | B9: 2026-05-11 | C9: CC-CC003-0062 | D9: TAM | E9: Country Bread | F9: Brioche Sandwich | G9: 10pcs Loaf | H9: 12 | I9: 10 | J9: =H9*I9 | K9: 15.5 | L9: 186
A10: 2026-05 | B10: 2026-05-11 | C10: CC-CC003-0063 | D10: TAM | E10: Country Bread | F10: Brioche Sandwich | G10: 10pcs Loaf | H10: 14 | I10: 10 | J10: =H10*I10 | K10: 15.5 | L10: 217
A11: 2026-05 | B11: 2026-05-11 | C11: CC-CC003-0064 | D11: TAM | E11: Country Bread | F11: Brioche Sandwich | G11: 10pcs Loaf | H11: 24 | I11: 10 | J11: =H11*I11 | K11: 15.5 | L11: 372
A12: 2026-06 | B12: 2026-06-17 | C12: CC-CC001-0217 | D12: PJ | E12: Country Bread | F12: Brioche Sandwich | G12: 10pcs Loaf | H12: 174 | I12: 10 | J12: =H12*I12 | K12: 16.19 | L12: 2817
A13: 2026-06 | B13: 2026-06-17 | C13: CC-CC003-0141 | D13: TAM | E13: Country Bread | F13: Brioche Sandwich | G13: 10pcs Loaf | H13: 71 | I13: 10 | J13: =H13*I13 | K13: 16.63 | L13: 1180.5
... A384: 2026-07 | B384: 2026-07-23 | C384: PC-CC002-0182 | D384: SA | E384: Ad-hoc Purchase | F384: Udang | G384: Pack (1000g) | H384: 1 | I384: 1000 | J384: =H384*I384 | K384: 38.2 | L384: 38.2
